<?xml version="1.0" encoding="utf-8"?>
<!-- This URDF was automatically created by SolidWorks to URDF Exporter! Originally created by Stephen Brawner (brawner@gmail.com) 
     Commit Version: 1.5.1-0-g916b5db  Build Version: 1.5.7152.31018
     For more information, please see http://wiki.ros.org/sw_urdf_exporter -->
<robot
  name="mkmr_urdf">
  <link
    name="base_link">
    <inertial>
      <origin
        xyz="-0.0268483686387245 1.21607692108899E-09 -0.00150000000000019"
        rpy="0 0 0" />
      <mass
        value="0.103562496069832" />
      <inertia
        ixx="0.000191833350350532"
        ixy="1.43353504923239E-11"
        ixz="-3.78740971049399E-18"
        iyy="0.000540911588861398"
        iyz="-2.42123745732002E-16"
        izz="0.000732589595457573" />
    </inertial>
    <visual>
      <origin
        xyz="0 0 0"
        rpy="0 0 0" />
      <geometry>
        <mesh
          filename="package://mkmr_urdf/meshes/base_link.STL" />
      </geometry>
      <material
        name="">
        <color
          rgba="0 0 0 1" />
      </material>
    </visual>
    <collision>
      <origin
        xyz="0 0 0"
        rpy="0 0 0" />
      <geometry>
        <mesh
          filename="package://mkmr_urdf/meshes/base_link.STL" />
      </geometry>
    </collision>
  </link>
  <link
    name="chasis_link">
    <inertial>
      <origin
        xyz="0 4.33680868994202E-18 0"
        rpy="0 0 0" />
      <mass
        value="0.00099698897376" />
      <inertia
        ixx="1.67290127091386E-08"
        ixy="3.02965701463008E-25"
        ixz="-1.09254015306004E-24"
        iyy="1.67290127091386E-08"
        iyz="1.20802494059152E-24"
        izz="1.63055612499839E-08" />
    </inertial>
    <visual>
      <origin
        xyz="0 0 0"
        rpy="0 0 0" />
      <geometry>
        <mesh
          filename="package://mkmr_urdf/meshes/chasis_link.STL" />
      </geometry>
      <material
        name="">
        <color
          rgba="0.792156862745098 0.819607843137255 0.933333333333333 1" />
      </material>
    </visual>
    <collision>
      <origin
        xyz="0 0 0"
        rpy="0 0 0" />
      <geometry>
        <mesh
          filename="package://mkmr_urdf/meshes/chasis_link.STL" />
      </geometry>
    </collision>
  </link>
  <joint
    name="chasis_joint"
    type="fixed">
    <origin
      xyz="-0.032984000000001 0.0355 0"
      rpy="1.5707963267949 0 0" />
    <parent
      link="base_link" />
    <child
      link="chasis_link" />
    <axis
      xyz="0 0 0" />
  </joint>
  <link
    name="front_left_wheel">
    <inertial>
      <origin
        xyz="2.20994875353708E-06 0.0137458677668464 1.25513774644481E-07"
        rpy="0 0 0" />
      <mass
        value="0.0476116186505196" />
      <inertia
        ixx="5.15038604464735E-06"
        ixy="-1.76170105615123E-11"
        ixz="-2.4535690082023E-20"
        iyy="6.47263266606936E-06"
        iyz="2.97339522986395E-13"
        izz="5.15038633208784E-06" />
    </inertial>
    <visual>
      <origin
        xyz="0 0 0"
        rpy="0 0 0" />
      <geometry>
        <mesh
          filename="package://mkmr_urdf/meshes/front_left_wheel.STL" />
      </geometry>
      <material
        name="">
        <color
          rgba="0.901960784313726 0.901960784313726 0.901960784313726 1" />
      </material>
    </visual>
    <collision>
      <origin
        xyz="0 0 0"
        rpy="0 0 0" />
      <geometry>
        <mesh
          filename="package://mkmr_urdf/meshes/front_left_wheel.STL" />
      </geometry>
    </collision>
  </link>
  <joint
    name="front_left_wheel_joint"
    type="continuous">
    <origin
      xyz="0.0824840000000006 0.0945000000000005 0"
      rpy="3.14159265358979 0 -3.14159265358979" />
    <parent
      link="chasis_link" />
    <child
      link="front_left_wheel" />
    <axis
      xyz="0 1 0" />
  </joint>
  <link
    name="back_left_wheel">
    <inertial>
      <origin
        xyz="2.12436712182518E-06 -0.0157458805750022 -1.93716828342239E-08"
        rpy="0 0 0" />
      <mass
        value="0.0476113796200164" />
      <inertia
        ixx="5.15036176146399E-06"
        ixy="-1.30467727967778E-12"
        ixz="-9.23224471388305E-20"
        iyy="6.47262631898505E-06"
        iyz="9.76993198685751E-12"
        izz="5.15036425603524E-06" />
    </inertial>
    <visual>
      <origin
        xyz="0 0 0"
        rpy="0 0 0" />
      <geometry>
        <mesh
          filename="package://mkmr_urdf/meshes/back_left_wheel.STL" />
      </geometry>
      <material
        name="">
        <color
          rgba="0.901960784313726 0.901960784313726 0.901960784313726 1" />
      </material>
    </visual>
    <collision>
      <origin
        xyz="0 0 0"
        rpy="0 0 0" />
      <geometry>
        <mesh
          filename="package://mkmr_urdf/meshes/back_left_wheel.STL" />
      </geometry>
    </collision>
  </link>
  <joint
    name="back_left_wheel_joint"
    type="continuous">
    <origin
      xyz="-0.0825159999999995 0.0924999999999993 0"
      rpy="-3.14159265358979 0 0" />
    <parent
      link="chasis_link" />
    <child
      link="back_left_wheel" />
    <axis
      xyz="0 0 0" />
  </joint>
  <link
    name="back_right_wheel">
    <inertial>
      <origin
        xyz="2.20994875367586E-06 0.0137458677668464 1.25513774637542E-07"
        rpy="0 0 0" />
      <mass
        value="0.0476116186505194" />
      <inertia
        ixx="5.15038604464734E-06"
        ixy="-1.76170105514142E-11"
        ixz="-2.37209903390197E-20"
        iyy="6.47263266606935E-06"
        iyz="2.973395247499E-13"
        izz="5.15038633208782E-06" />
    </inertial>
    <visual>
      <origin
        xyz="0 0 0"
        rpy="0 0 0" />
      <geometry>
        <mesh
          filename="package://mkmr_urdf/meshes/back_right_wheel.STL" />
      </geometry>
      <material
        name="">
        <color
          rgba="0.901960784313726 0.901960784313726 0.901960784313726 1" />
      </material>
    </visual>
    <collision>
      <origin
        xyz="0 0 0"
        rpy="0 0 0" />
      <geometry>
        <mesh
          filename="package://mkmr_urdf/meshes/back_right_wheel.STL" />
      </geometry>
    </collision>
  </link>
  <joint
    name="back_right_wheel_joint"
    type="continuous">
    <origin
      xyz="-0.0825159999999981 -0.0945000000000007 0"
      rpy="-3.14159265358979 0 0" />
    <parent
      link="chasis_link" />
    <child
      link="back_right_wheel" />
    <axis
      xyz="0 0 0" />
  </joint>
  <link
    name="front_right_wheel">
    <inertial>
      <origin
        xyz="2.12436712201253E-06 -0.0157458805750022 -1.93716828411628E-08"
        rpy="0 0 0" />
      <mass
        value="0.0476113796200165" />
      <inertia
        ixx="5.150361761464E-06"
        ixy="-1.30467729016545E-12"
        ixz="-9.18556123580339E-20"
        iyy="6.47262631898505E-06"
        iyz="9.76993198498412E-12"
        izz="5.15036425603525E-06" />
    </inertial>
    <visual>
      <origin
        xyz="0 0 0"
        rpy="0 0 0" />
      <geometry>
        <mesh
          filename="package://mkmr_urdf/meshes/front_right_wheel.STL" />
      </geometry>
      <material
        name="">
        <color
          rgba="0.901960784313726 0.901960784313726 0.901960784313726 1" />
      </material>
    </visual>
    <collision>
      <origin
        xyz="0 0 0"
        rpy="0 0 0" />
      <geometry>
        <mesh
          filename="package://mkmr_urdf/meshes/front_right_wheel.STL" />
      </geometry>
    </collision>
  </link>
  <joint
    name="front_right_wheel_joint"
    type="continuous">
    <origin
      xyz="0.0824840000000019 -0.0924999999999995 0"
      rpy="3.14159265358979 0 -3.14159265358979" />
    <parent
      link="chasis_link" />
    <child
      link="front_right_wheel" />
    <axis
      xyz="0 1 0" />
  </joint>
  <link
    name="fMotorBracket">
    <inertial>
      <origin
        xyz="-0.0610000000000015 -0.0674547790002785 -0.0116887463358963"
        rpy="0 0 0" />
      <mass
        value="0.012334653543211" />
      <inertia
        ixx="3.51055038644331E-06"
        ixy="-6.12729326621837E-19"
        ixz="8.524624284462E-17"
        iyy="3.95634077909559E-06"
        iyz="1.11448332781975E-19"
        izz="3.62492890882267E-06" />
    </inertial>
    <visual>
      <origin
        xyz="0 0 0"
        rpy="0 0 0" />
      <geometry>
        <mesh
          filename="package://mkmr_urdf/meshes/fMotorBracket.STL" />
      </geometry>
      <material
        name="">
        <color
          rgba="0.752941176470588 0.752941176470588 0.752941176470588 1" />
      </material>
    </visual>
    <collision>
      <origin
        xyz="0 0 0"
        rpy="0 0 0" />
      <geometry>
        <mesh
          filename="package://mkmr_urdf/meshes/fMotorBracket.STL" />
      </geometry>
    </collision>
  </link>
  <joint
    name="fMotorBracket_joint"
    type="fixed">
    <origin
      xyz="0.0345000000000004 0 -0.0609999999999998"
      rpy="1.5707963267949 1.5707963267949 0" />
    <parent
      link="base_link" />
    <child
      link="fMotorBracket" />
    <axis
      xyz="0 0 0" />
  </joint>
  <link
    name="fMotor">
    <inertial>
      <origin
        xyz="0.0012598162449621 0.0824999999999999 -0.079"
        rpy="0 0 0" />
      <mass
        value="0.212405766227002" />
      <inertia
        ixx="5.17259698645822E-05"
        ixy="-5.07691498136368E-23"
        ixz="-7.9467054546941E-20"
        iyy="5.18506671512217E-05"
        iyz="2.71802092193946E-07"
        izz="2.83766813003582E-05" />
    </inertial>
    <visual>
      <origin
        xyz="0 0 0"
        rpy="0 0 0" />
      <geometry>
        <mesh
          filename="package://mkmr_urdf/meshes/fMotor.STL" />
      </geometry>
      <material
        name="">
        <color
          rgba="0.792156862745098 0.819607843137255 0.933333333333333 1" />
      </material>
    </visual>
    <collision>
      <origin
        xyz="0 0 0"
        rpy="0 0 0" />
      <geometry>
        <mesh
          filename="package://mkmr_urdf/meshes/fMotor.STL" />
      </geometry>
    </collision>
  </link>
  <joint
    name="fMotor_joint"
    type="fixed">
    <origin
      xyz="0.0179999999999999 -0.15 -0.0285000000000011"
      rpy="0 1.5707963267949 0" />
    <parent
      link="fMotorBracket" />
    <child
      link="fMotor" />
    <axis
      xyz="0 0 0" />
  </joint>
  <link
    name="scan">
    <inertial>
      <origin
        xyz="-0.00748346988333638 0.0106681277328402 9.19261110875341E-05"
        rpy="0 0 0" />
      <mass
        value="1.33076913637071" />
      <inertia
        ixx="0.00061491794045409"
        ixy="0.00015824302591117"
        ixz="8.01984318975029E-07"
        iyy="0.00109815200027136"
        iyz="3.09162986587569E-06"
        izz="0.000960697335617222" />
    </inertial>
    <visual>
      <origin
        xyz="0 0 0"
        rpy="0 0 0" />
      <geometry>
        <mesh
          filename="package://mkmr_urdf/meshes/scan.STL" />
      </geometry>
      <material
        name="">
        <color
          rgba="0.792156862745098 0.819607843137255 0.933333333333333 1" />
      </material>
    </visual>
    <collision>
      <origin
        xyz="0 0 0"
        rpy="0 0 0" />
      <geometry>
        <mesh
          filename="package://mkmr_urdf/meshes/scan.STL" />
      </geometry>
    </collision>
  </link>
  <joint
    name="scan_joint"
    type="fixed">
    <origin
      xyz="0.054864 -0.0860200000000002 -0.000761999999999532"
      rpy="3.14159265358979 1.5707963267949 0" />
    <parent
      link="base_link" />
    <child
      link="scan" />
    <axis
      xyz="0 0 0" />
  </joint>
  <link
    name="camera">
    <inertial>
      <origin
        xyz="-1.97527361641553E-06 0.00684696741341874 -0.00214510583885713"
        rpy="0 0 0" />
      <mass
        value="0.0025100794824479" />
      <inertia
        ixx="9.33506839168769E-08"
        ixy="-4.61883617782687E-12"
        ixz="-3.33058515401231E-11"
        iyy="1.4088644495438E-07"
        iyz="4.33753765925423E-09"
        izz="8.821660212487E-08" />
    </inertial>
    <visual>
      <origin
        xyz="0 0 0"
        rpy="0 0 0" />
      <geometry>
        <mesh
          filename="package://mkmr_urdf/meshes/camera.STL" />
      </geometry>
      <material
        name="">
        <color
          rgba="0.752941176470588 0.752941176470588 0.752941176470588 1" />
      </material>
    </visual>
    <collision>
      <origin
        xyz="0 0 0"
        rpy="0 0 0" />
      <geometry>
        <mesh
          filename="package://mkmr_urdf/meshes/camera.STL" />
      </geometry>
    </collision>
  </link>
  <joint
    name="camera_joint"
    type="fixed">
    <origin
      xyz="0.08282 -0.0734200000000002 -0.036649"
      rpy="1.5707963267949 1.5707963267949 0" />
    <parent
      link="base_link" />
    <child
      link="camera" />
    <axis
      xyz="0 0 0" />
  </joint>
  <link
    name="fPC">
    <inertial>
      <origin
        xyz="-2.40586424375708E-18 0 0"
        rpy="0 0 0" />
      <mass
        value="0.8130163223512" />
      <inertia
        ixx="0.001459055406619"
        ixy="3.99889838699416E-20"
        ixz="-7.176882190073E-20"
        iyy="0.00195188655713094"
        iyz="1.15181796798229E-19"
        izz="0.000955287897127547" />
    </inertial>
    <visual>
      <origin
        xyz="0 0 0"
        rpy="0 0 0" />
      <geometry>
        <mesh
          filename="package://mkmr_urdf/meshes/fPC.STL" />
      </geometry>
      <material
        name="">
        <color
          rgba="0.501960784313725 0.501960784313725 0.501960784313725 1" />
      </material>
    </visual>
    <collision>
      <origin
        xyz="0 0 0"
        rpy="0 0 0" />
      <geometry>
        <mesh
          filename="package://mkmr_urdf/meshes/fPC.STL" />
      </geometry>
    </collision>
  </link>
  <joint
    name="fPC_joint"
    type="fixed">
    <origin
      xyz="0.02413 -0.0322100000000002 0"
      rpy="3.14159265358979 1.5707963267949 0" />
    <parent
      link="base_link" />
    <child
      link="fPC" />
    <axis
      xyz="0 0 0" />
  </joint>
  <link
    name="fDrivers">
    <inertial>
      <origin
        xyz="-0.00662680497475599 0.0454090890784855 -0.00384423999850007"
        rpy="0 0 0" />
      <mass
        value="0.0384827950773915" />
      <inertia
        ixx="9.00094025592023E-06"
        ixy="1.23322080099711E-07"
        ixz="1.33828604274648E-07"
        iyy="2.17073673470651E-05"
        iyz="7.70745836412046E-07"
        izz="2.83840013362901E-05" />
    </inertial>
    <visual>
      <origin
        xyz="0 0 0"
        rpy="0 0 0" />
      <geometry>
        <mesh
          filename="package://mkmr_urdf/meshes/fDrivers.STL" />
      </geometry>
      <material
        name="">
        <color
          rgba="0.792156862745098 0.819607843137255 0.933333333333333 1" />
      </material>
    </visual>
    <collision>
      <origin
        xyz="0 0 0"
        rpy="0 0 0" />
      <geometry>
        <mesh
          filename="package://mkmr_urdf/meshes/fDrivers.STL" />
      </geometry>
    </collision>
  </link>
  <joint
    name="fDrivers_joint"
    type="fixed">
    <origin
      xyz="-0.0399479 0.00465100000000018 0.037726592766333"
      rpy="-1.5707963267949 0 -3.14159265358979" />
    <parent
      link="base_link" />
    <child
      link="fDrivers" />
    <axis
      xyz="0 0 0" />
  </joint>
  <link
    name="fBattery">
    <inertial>
      <origin
        xyz="1.38777878078145E-17 -6.93889390390723E-18 1.57000591617927E-16"
        rpy="0 0 0" />
      <mass
        value="0.97961835817872" />
      <inertia
        ixx="0.0016474672455433"
        ixy="7.03543185374577E-20"
        ixz="-2.37638873019888E-20"
        iyy="0.00178853200699095"
        iyz="-3.34779396182049E-20"
        izz="0.0014610820587575" />
    </inertial>
    <visual>
      <origin
        xyz="0 0 0"
        rpy="0 0 0" />
      <geometry>
        <mesh
          filename="package://mkmr_urdf/meshes/fBattery.STL" />
      </geometry>
      <material
        name="">
        <color
          rgba="1 1 1 1" />
      </material>
    </visual>
    <collision>
      <origin
        xyz="0 0 0"
        rpy="0 0 0" />
      <geometry>
        <mesh
          filename="package://mkmr_urdf/meshes/fBattery.STL" />
      </geometry>
    </collision>
  </link>
  <joint
    name="fBattery_joint"
    type="fixed">
    <origin
      xyz="-0.09476040070881 -0.047958 0"
      rpy="-3.14159265358979 0 0" />
    <parent
      link="base_link" />
    <child
      link="fBattery" />
    <axis
      xyz="0 0 0" />
  </joint>
</robot>